Workbook

Sheet はじめに
B1: ♡ ゆるり家計簿｜年間イベント費 積立ノート ♡
B2: 「毎年あるのに、なぜか突然に感じる出費」を、毎月ちょっとずつ積み立てて準備するためのシートです。
B4: まずはここから（3ステップ）
B5: ① 設定 | C5: 「設定」シートで開始年・開始月を入れ、イベント項目と年間予算を自分用に書き換えます。初期値は例なので、そのまま使ってもOKです。
B6: ② 入力 | C6: 「入力」シートに、使った日・項目・金額を入れるだけ。スマホからでも、このシートだけ使えば完了です。
B7: ③ ホーム | C7: 「ホーム」シートで、予算の残りと積立の目安が自動で見られます。ここは触らなくて大丈夫です。
B9: 色のルール
B10: クリーム色 | C10: 入力するところです。
B11: 白・ピンク・ミント | C11: 自動で計算されるところです（触らなくてOK）。
B13: シートの説明
B14: ホーム | C14: 年間予算・使った額・残り・積立残高を、項目ごとに一覧で確認できます。予算オーバーは赤く表示されます。
B15: 入力 | C15: 使ったお金を記録します。右端の「チェック」欄が、未入力・期間外・項目名の違いを教えてくれます。
B16: 設定 | C16: 開始年・開始月、イベント項目、年間予算、支払予定月、最初から貯めてある額を決めます。
B17: 月別 | C17: 月ごとの実績・支払い予定・積立残高の推移を見られます。
B19: 積立額の考え方
B20: 計算式 | C20: 毎月の積立＝年間予算÷12（切り上げ）／積立残高＝最初から貯めてある額＋毎月の積立×経過月数－使った額。実際に口座を分ける必要はなく、「いくら取り分けておくと安心か」の目安として使います。
B22: スマホ・iPadで使うとき
B23: おすすめの方法 | C23: 無料の「Googleスプレッドシート」アプリが、iPhone・Android・iPadのどれでも使えておすすめです。日々の入力は「入力」タブだけで完了します。
B24: 最初の準備（パソコンで1回だけ） | C24: ① Googleドライブにこのファイルをアップロードします。② ファイルを右クリックして「アプリで開く」→「Googleスプレッドシート」を選びます。③ 「ファイル」→「Googleスプレッドシートとして保存」を選びます。これでExcel形式ではなく、スプレッドシートとして使えます。
B25: スマホ・iPadでの使い方 | C25: ① アプリ「Googleスプレッドシート」を入れ、同じGoogleアカウントでログインします。② 変換したファイルを開き、下の「入力」タブを選びます。③ 空いている行に、日付・項目・金額を入れます（項目はリストから選べます）。④ 「ホーム」タブで、残りの予算と積立残高を確認します。
B26: 使いやすくするコツ | C26: ・日付は「2026/9/29」のように、年から入れると確実です。・「ホーム」と「月別」は幅が広いので、画面を横向きにすると見やすくなります。・アプリの「オフラインで使用可能にする」をオンにすると、電波が弱い場所でも入力できます。・ホーム画面にショートカットを置くと、すぐ開けます。
B27: Excelアプリの場合 | C27: Microsoft ExcelアプリでもExcelファイルのまま開けます。画面サイズやアカウントによっては、編集に有料プランが必要な場合があります。
B28: iPad標準のNumbers | C28: 表示や動作を保証できないため、おすすめしません。Googleスプレッドシートをご利用ください。
B29: うまく動かないとき | C29: 「Googleスプレッドシートとして保存」できているか（Excel形式のままだと崩れる場合があります）、入力シートの日付が設定した期間内か、項目がリストの名前と一致しているかをご確認ください。
B31: よくある質問
B32: 行が足りなくなったら？ | C32: 「入力」シートは1,000行分があらかじめ集計の対象です。それでも足りないときは、データの途中に行を挿入すると集計範囲も自動で広がります。
B33: 並べ替えても大丈夫？ | C33: 大丈夫です。集計は行の位置ではなく「日付」と「項目」の条件で行うため、並べ替え・行の挿入・削除をしても崩れません。
B34: 項目名を変えたら？ | C34: 設定シートの項目名を変えたときは、入力シート側の同じ名前も直してください（名前が一致した行だけ集計されます）。「検索と置換」が便利です。一致しない行は「⚠項目不明」と表示されます。
B35: 来年も使えますか？ | C35: ファイルをコピーして「開始年」を変え、入力シートの日付・項目・金額・メモを消去してください（チェック欄の式は残します）。余った積立は「最初から貯めてある額」に入れると引き継げます。
B36: 何月始まりでもOK？ | C36: はい。設定シートの開始月を変えるだけで、4月始まりなども自由に設定できます。
B37: Excel／Googleスプレッドシート | C37: どちらでも使えるよう、基本的な関数だけで作っています。Googleスプレッドシートで使う場合は、Googleドライブにアップロードして、右クリックから「Googleスプレッドシートで開く」を選んでください。
B38: シートを誤って壊したくない | C38: ホーム・月別・設定は、計算式のセルを保護しています（パスワードなし）。解除したいときは、Excelは「校閲」→「シート保護の解除」、Googleスプレッドシートは保護の設定から外せます。
B40: ご利用にあたって
B41: 個人利用 | C41: 個人利用に限ります。再配布・転売・無料公開はお控えください。ご自身用に色や項目を変えるのは自由です。
B42: 返品・返金 | C42: デジタル商品のため、購入後の返品・返金には対応できません。
B43: 販売元 | C43: 株式会社PRIAMOS（ブランド：ゆるり家計簿） © 株式会社PRIAMOS All rights reserved.

Sheet ホーム
B1: ♡ ゆるり家計簿｜年間イベント費 積立ノート ♡
B2: ="集計期間："&TEXT(設定!C8,"yyyy年m月d日")&" 〜 "&TEXT(設定!C9,"yyyy年m月d日") -> 集計期間：2026年1月1日 〜 2026年12月31日
B4: 年間予算の合計 | D4: =C28 -> 460000
B5: ここまでに使った額 | D5: =D28 -> 0
B6: 残りの予算 | D6: =E28 -> 460000
B7: 毎月の積立目安 | D7: =G28 -> 38336
B8: いまの積立残高（目安） | D8: =H28 -> 345024
B9: 入力チェック | D9: =IF(COUNTIF(入力!$E$5:$E$1004,"⚠*")=0,"問題なし ♡",COUNTIF(入力!$E$5:$E$1004,"⚠*")&"件 要確認（入力シート）") -> 問題なし ♡
B10: =IF(COUNTIF(E13:E27,"<0")>0,"予算オーバーの項目があります。内訳を見直してみましょう","順調です ♡ この調子でコツコツ積み立てましょう") -> 順調です ♡ この調子でコツコツ積み立てましょう
B12: 項目 | C12: 年間予算 | D12: 使った額 | E12: 残り | F12: 使用状況 | G12: 毎月の積立 | H12: 積立残高
B13: =IF(設定!B15="","",設定!B15) -> 帰省・旅行 | C13: =IF($B13="","",N(設定!C15)) -> 80000 | D13: =IF($B13="","",SUMIFS(入力!$C$5:$C$1004,入力!$B$5:$B$1004,$B13,入力!$A$5:$A$1004,">="&設定!$C$8,入力!$A$5:$A$1004,"<="&設定!$C$9)) -> 0 | E13: =IF($B13="","",C13-D13) -> 80000 | F13: =IF($B13="","",IF(C13<=0,"予算未設定",REPT("■",MIN(10,ROUND(D13/C13*10,0)))&REPT("□",10-MIN(10,ROUND(D13/C13*10,0)))&" "&TEXT(D13/C13,"0%"))) -> □□□□□□□□□□ 0% | G13: =IF($B13="","",ROUNDUP(C13/12,0)) -> 6667 | H13: =IF($B13="","",N(設定!E15)+G13*設定!$C$11-D13) -> 60003
B14: =IF(設定!B16="","",設定!B16) -> 冠婚葬祭（ご祝儀・香典） | C14: =IF($B14="","",N(設定!C16)) -> 60000 | D14: =IF($B14="","",SUMIFS(入力!$C$5:$C$1004,入力!$B$5:$B$1004,$B14,入力!$A$5:$A$1004,">="&設定!$C$8,入力!$A$5:$A$1004,"<="&設定!$C$9)) -> 0 | E14: =IF($B14="","",C14-D14) -> 60000 | F14: =IF($B14="","",IF(C14<=0,"予算未設定",REPT("■",MIN(10,ROUND(D14/C14*10,0)))&REPT("□",10-MIN(10,ROUND(D14/C14*10,0)))&" "&TEXT(D14/C14,"0%"))) -> □□□□□□□□□□ 0% | G14: =IF($B14="","",ROUNDUP(C14/12,0)) -> 5000 | H14: =IF($B14="","",N(設定!E16)+G14*設定!$C$11-D14) -> 45000
B15: =IF(設定!B17="","",設定!B17) -> 誕生日・記念日 | C15: =IF($B15="","",N(設定!C17)) -> 30000 | D15: =IF($B15="","",SUMIFS(入力!$C$5:$C$1004,入力!$B$5:$B$1004,$B15,入力!$A$5:$A$1004,">="&設定!$C$8,入力!$A$5:$A$1004,"<="&設定!$C$9)) -> 0 | E15: =IF($B15="","",C15-D15) -> 30000 | F15: =IF($B15="","",IF(C15<=0,"予算未設定",REPT("■",MIN(10,ROUND(D15/C15*10,0)))&REPT("□",10-MIN(10,ROUND(D15/C15*10,0)))&" "&TEXT(D15/C15,"0%"))) -> □□□□□□□□□□ 0% | G15: =IF($B15="","",ROUNDUP(C15/12,0)) -> 2500 | H15: =IF($B15="","",N(設定!E17)+G15*設定!$C$11-D15) -> 22500
B16: =IF(設定!B18="","",設定!B18) -> クリスマス・年末年始 | C16: =IF($B16="","",N(設定!C18)) -> 40000 | D16: =IF($B16="","",SUMIFS(入力!$C$5:$C$1004,入力!$B$5:$B$1004,$B16,入力!$A$5:$A$1004,">="&設定!$C$8,入力!$A$5:$A$1004,"<="&設定!$C$9)) -> 0 | E16: =IF($B16="","",C16-D16) -> 40000 | F16: =IF($B16="","",IF(C16<=0,"予算未設定",REPT("■",MIN(10,ROUND(D16/C16*10,0)))&REPT("□",10-MIN(10,ROUND(D16/C16*10,0)))&" "&TEXT(D16/C16,"0%"))) -> □□□□□□□□□□ 0% | G16: =IF($B16="","",ROUNDUP(C16/12,0)) -> 3334 | H16: =IF($B16="","",N(設定!E18)+G16*設定!$C$11-D16) -> 30006
B17: =IF(設定!B19="","",設定!B19) -> お中元・お歳暮 | C17: =IF($B17="","",N(設定!C19)) -> 20000 | D17: =IF($B17="","",SUMIFS(入力!$C$5:$C$1004,入力!$B$5:$B$1004,$B17,入力!$A$5:$A$1004,">="&設定!$C$8,入力!$A$5:$A$1004,"<="&設定!$C$9)) -> 0 | E17: =IF($B17="","",C17-D17) -> 20000 | F17: =IF($B17="","",IF(C17<=0,"予算未設定",REPT("■",MIN(10,ROUND(D17/C17*10,0)))&REPT("□",10-MIN(10,ROUND(D17/C17*10,0)))&" "&TEXT(D17/C17,"0%"))) -> □□□□□□□□□□ 0% | G17: =IF($B17="","",ROUNDUP(C17/12,0)) -> 1667 | H17: =IF($B17="","",N(設定!E19)+G17*設定!$C$11-D17) -> 15003
B18: =IF(設定!B20="","",設定!B20) -> 美容（ヘア・ネイル） | C18: =IF($B18="","",N(設定!C20)) -> 60000 | D18: =IF($B18="","",SUMIFS(入力!$C$5:$C$1004,入力!$B$5:$B$1004,$B18,入力!$A$5:$A$1004,">="&設定!$C$8,入力!$A$5:$A$1004,"<="&設定!$C$9)) -> 0 | E18: =IF($B18="","",C18-D18) -> 60000 | F18: =IF($B18="","",IF(C18<=0,"予算未設定",REPT("■",MIN(10,ROUND(D18/C18*10,0)))&REPT("□",10-MIN(10,ROUND(D18/C18*10,0)))&" "&TEXT(D18/C18,"0%"))) -> □□□□□□□□□□ 0% | G18: =IF($B18="","",ROUNDUP(C18/12,0)) -> 5000 | H18: =IF($B18="","",N(設定!E20)+G18*設定!$C$11-D18) -> 45000
B19: =IF(設定!B21="","",設定!B21) -> 推し活・イベント | C19: =IF($B19="","",N(設定!C21)) -> 50000 | D19: =IF($B19="","",SUMIFS(入力!$C$5:$C$1004,入力!$B$5:$B$1004,$B19,入力!$A$5:$A$1004,">="&設定!$C$8,入力!$A$5:$A$1004,"<="&設定!$C$9)) -> 0 | E19: =IF($B19="","",C19-D19) -> 50000 | F19: =IF($B19="","",IF(C19<=0,"予算未設定",REPT("■",MIN(10,ROUND(D19/C19*10,0)))&REPT("□",10-MIN(10,ROUND(D19/C19*10,0)))&" "&TEXT(D19/C19,"0%"))) -> □□□□□□□□□□ 0% | G19: =IF($B19="","",ROUNDUP(C19/12,0)) -> 4167 | H19: =IF($B19="","",N(設定!E21)+G19*設定!$C$11-D19) -> 37503
B20: =IF(設定!B22="","",設定!B22) -> 家電・家具の買い替え | C20: =IF($B20="","",N(設定!C22)) -> 40000 | D20: =IF($B20="","",SUMIFS(入力!$C$5:$C$1004,入力!$B$5:$B$1004,$B20,入力!$A$5:$A$1004,">="&設定!$C$8,入力!$A$5:$A$1004,"<="&設定!$C$9)) -> 0 | E20: =IF($B20="","",C20-D20) -> 40000 | F20: =IF($B20="","",IF(C20<=0,"予算未設定",REPT("■",MIN(10,ROUND(D20/C20*10,0)))&REPT("□",10-MIN(10,ROUND(D20/C20*10,0)))&" "&TEXT(D20/C20,"0%"))) -> □□□□□□□□□□ 0% | G20: =IF($B20="","",ROUNDUP(C20/12,0)) -> 3334 | H20: =IF($B20="","",N(設定!E22)+G20*設定!$C$11-D20) -> 30006
B21: =IF(設定!B23="","",設定!B23) -> 資格・習い事 | C21: =IF($B21="","",N(設定!C23)) -> 30000 | D21: =IF($B21="","",SUMIFS(入力!$C$5:$C$1004,入力!$B$5:$B$1004,$B21,入力!$A$5:$A$1004,">="&設定!$C$8,入力!$A$5:$A$1004,"<="&設定!$C$9)) -> 0 | E21: =IF($B21="","",C21-D21) -> 30000 | F21: =IF($B21="","",IF(C21<=0,"予算未設定",REPT("■",MIN(10,ROUND(D21/C21*10,0)))&REPT("□",10-MIN(10,ROUND(D21/C21*10,0)))&" "&TEXT(D21/C21,"0%"))) -> □□□□□□□□□□ 0% | G21: =IF($B21="","",ROUNDUP(C21/12,0)) -> 2500 | H21: =IF($B21="","",N(設定!E23)+G21*設定!$C$11-D21) -> 22500
B22: =IF(設定!B24="","",設定!B24) -> 年払い（保険・サブスク） | C22: =IF($B22="","",N(設定!C24)) -> 30000 | D22: =IF($B22="","",SUMIFS(入力!$C$5:$C$1004,入力!$B$5:$B$1004,$B22,入力!$A$5:$A$1004,">="&設定!$C$8,入力!$A$5:$A$1004,"<="&設定!$C$9)) -> 0 | E22: =IF($B22="","",C22-D22) -> 30000 | F22: =IF($B22="","",IF(C22<=0,"予算未設定",REPT("■",MIN(10,ROUND(D22/C22*10,0)))&REPT("□",10-MIN(10,ROUND(D22/C22*10,0)))&" "&TEXT(D22/C22,"0%"))) -> □□□□□□□□□□ 0% | G22: =IF($B22="","",ROUNDUP(C22/12,0)) -> 2500 | H22: =IF($B22="","",N(設定!E24)+G22*設定!$C$11-D22) -> 22500
B23: =IF(設定!B25="","",設定!B25) -> その他（予備費） | C23: =IF($B23="","",N(設定!C25)) -> 20000 | D23: =IF($B23="","",SUMIFS(入力!$C$5:$C$1004,入力!$B$5:$B$1004,$B23,入力!$A$5:$A$1004,">="&設定!$C$8,入力!$A$5:$A$1004,"<="&設定!$C$9)) -> 0 | E23: =IF($B23="","",C23-D23) -> 20000 | F23: =IF($B23="","",IF(C23<=0,"予算未設定",REPT("■",MIN(10,ROUND(D23/C23*10,0)))&REPT("□",10-MIN(10,ROUND(D23/C23*10,0)))&" "&TEXT(D23/C23,"0%"))) -> □□□□□□□□□□ 0% | G23: =IF($B23="","",ROUNDUP(C23/12,0)) -> 1667 | H23: =IF($B23="","",N(設定!E25)+G23*設定!$C$11-D23) -> 15003
B24: =IF(設定!B26="","",設定!B26) | C24: =IF($B24="","",N(設定!C26)) | D24: =IF($B24="","",SUMIFS(入力!$C$5:$C$1004,入力!$B$5:$B$1004,$B24,入力!$A$5:$A$1004,">="&設定!$C$8,入力!$A$5:$A$1004,"<="&設定!$C$9)) | E24: =IF($B24="","",C24-D24) | F24: =IF($B24="","",IF(C24<=0,"予算未設定",REPT("■",MIN(10,ROUND(D24/C24*10,0)))&REPT("□",10-MIN(10,ROUND(D24/C24*10,0)))&" "&TEXT(D24/C24,"0%"))) | G24: =IF($B24="","",ROUNDUP(C24/12,0)) | H24: =IF($B24="","",N(設定!E26)+G24*設定!$C$11-D24)
... B27: =IF(設定!B29="","",設定!B29) | C27: =IF($B27="","",N(設定!C29)) | D27: =IF($B27="","",SUMIFS(入力!$C$5:$C$1004,入力!$B$5:$B$1004,$B27,入力!$A$5:$A$1004,">="&設定!$C$8,入力!$A$5:$A$1004,"<="&設定!$C$9)) | E27: =IF($B27="","",C27-D27) | F27: =IF($B27="","",IF(C27<=0,"予算未設定",REPT("■",MIN(10,ROUND(D27/C27*10,0)))&REPT("□",10-MIN(10,ROUND(D27/C27*10,0)))&" "&TEXT(D27/C27,"0%"))) | G27: =IF($B27="","",ROUNDUP(C27/12,0)) | H27: =IF($B27="","",N(設定!E29)+G27*設定!$C$11-D27)
B28: 合計 | C28: =SUM(C13:C27) -> 460000 | D28: =SUM(D13:D27) -> 0 | E28: =SUM(E13:E27) -> 460000 | G28: =SUM(G13:G27) -> 38336 | H28: =SUM(H13:H27) -> 345024
B30: 積立の考え方：毎月の積立＝年間予算÷12（切り上げ）／積立残高＝最初から貯めてある額＋毎月の積立×経過月数－使った額。実際に口座を分ける必要はなく、取り分けの目安です。

Sheet 入力
A1: 入力（使ったお金を記録）
A2: 日付・項目・金額の3つを入れるだけ。メモは自由です。右端の「チェック」に⚠が出たら見直してください。
A3: 日付 | B3: 項目 | C3: 金額（円） | D3: メモ | E3: チェック
A4: 46246 | B4: 帰省・旅行 | C4: 18500 | D4: 新幹線代 | E4: ← 記入例（集計されません）
E5: =IF(COUNTA(A5:D5)=0,"",IF(COUNTA(A5:C5)<3,"⚠未入力",IF(OR(A5<設定!$C$8,A5>設定!$C$9),"⚠期間外",IF(COUNTIF(設定!$B$15:$B$29,B5)=0,"⚠項目不明",""))))
E6: =IF(COUNTA(A6:D6)=0,"",IF(COUNTA(A6:C6)<3,"⚠未入力",IF(OR(A6<設定!$C$8,A6>設定!$C$9),"⚠期間外",IF(COUNTIF(設定!$B$15:$B$29,B6)=0,"⚠項目不明",""))))
E7: =IF(COUNTA(A7:D7)=0,"",IF(COUNTA(A7:C7)<3,"⚠未入力",IF(OR(A7<設定!$C$8,A7>設定!$C$9),"⚠期間外",IF(COUNTIF(設定!$B$15:$B$29,B7)=0,"⚠項目不明",""))))
E8: =IF(COUNTA(A8:D8)=0,"",IF(COUNTA(A8:C8)<3,"⚠未入力",IF(OR(A8<設定!$C$8,A8>設定!$C$9),"⚠期間外",IF(COUNTIF(設定!$B$15:$B$29,B8)=0,"⚠項目不明",""))))
E9: =IF(COUNTA(A9:D9)=0,"",IF(COUNTA(A9:C9)<3,"⚠未入力",IF(OR(A9<設定!$C$8,A9>設定!$C$9),"⚠期間外",IF(COUNTIF(設定!$B$15:$B$29,B9)=0,"⚠項目不明",""))))
E10: =IF(COUNTA(A10:D10)=0,"",IF(COUNTA(A10:C10)<3,"⚠未入力",IF(OR(A10<設定!$C$8,A10>設定!$C$9),"⚠期間外",IF(COUNTIF(設定!$B$15:$B$29,B10)=0,"⚠項目不明",""))))
E11: =IF(COUNTA(A11:D11)=0,"",IF(COUNTA(A11:C11)<3,"⚠未入力",IF(OR(A11<設定!$C$8,A11>設定!$C$9),"⚠期間外",IF(COUNTIF(設定!$B$15:$B$29,B11)=0,"⚠項目不明",""))))
E12: =IF(COUNTA(A12:D12)=0,"",IF(COUNTA(A12:C12)<3,"⚠未入力",IF(OR(A12<設定!$C$8,A12>設定!$C$9),"⚠期間外",IF(COUNTIF(設定!$B$15:$B$29,B12)=0,"⚠項目不明",""))))
E13: =IF(COUNTA(A13:D13)=0,"",IF(COUNTA(A13:C13)<3,"⚠未入力",IF(OR(A13<設定!$C$8,A13>設定!$C$9),"⚠期間外",IF(COUNTIF(設定!$B$15:$B$29,B13)=0,"⚠項目不明",""))))
E14: =IF(COUNTA(A14:D14)=0,"",IF(COUNTA(A14:C14)<3,"⚠未入力",IF(OR(A14<設定!$C$8,A14>設定!$C$9),"⚠期間外",IF(COUNTIF(設定!$B$15:$B$29,B14)=0,"⚠項目不明",""))))
E15: =IF(COUNTA(A15:D15)=0,"",IF(COUNTA(A15:C15)<3,"⚠未入力",IF(OR(A15<設定!$C$8,A15>設定!$C$9),"⚠期間外",IF(COUNTIF(設定!$B$15:$B$29,B15)=0,"⚠項目不明",""))))
E16: =IF(COUNTA(A16:D16)=0,"",IF(COUNTA(A16:C16)<3,"⚠未入力",IF(OR(A16<設定!$C$8,A16>設定!$C$9),"⚠期間外",IF(COUNTIF(設定!$B$15:$B$29,B16)=0,"⚠項目不明",""))))
... E1004: =IF(COUNTA(A1004:D1004)=0,"",IF(COUNTA(A1004:C1004)<3,"⚠未入力",IF(OR(A1004<設定!$C$8,A1004>設定!$C$9),"⚠期間外",IF(COUNTIF(設定!$B$15:$B$29,B1004)=0,"⚠項目不明",""))))

Sheet 設定
B2: 設定（最初にここだけ入力します）
B3: クリーム色のセルだけ入力してください。初期値は「例」なので、ご自身の暮らしに合わせて自由に書き換えてOKです。
B5: 開始年 | C5: 2026 | D5: 例：2026
B6: 開始月（何月始まりでもOK） | C6: 1 | D6: 1月始まり＝1 4月始まり＝4
B7: 基準日（空欄なら今日） | D7: 空欄のままでOK。過去の日で確認したいときだけ入力
B8: 集計期間の開始日 | C8: =DATE(C5,C6,1) -> 46023 | D8: 自動計算（触らなくてOK）
B9: 集計期間の終了日 | C9: =DATE(C5,C6+12,1)-1 -> 46387 | D9: 自動計算（触らなくてOK）
B10: 計算に使う日付 | C10: =IF(C7="",TODAY(),C7) -> 46294 | D10: 自動計算（触らなくてOK）
B11: 経過月数（積立の計算に使用） | C11: =MIN(12,MAX(0,(YEAR(C10)-C5)*12+MONTH(C10)-C6+1)) -> 9 | D11: 自動計算（触らなくてOK）
B13: イベント項目（最大15個・名前も金額も自由に変更できます）
B14: 項目名 | C14: 年間予算（円） | D14: 支払予定月 | E14: 最初から貯めてある額（円） | F14: メモ
B15: 帰省・旅行 | C15: 80000 | D15: 8 | E15: 0 | F15: お盆・GWなど
B16: 冠婚葬祭（ご祝儀・香典） | C16: 60000 | D16: 6 | E16: 0
B17: 誕生日・記念日 | C17: 30000 | D17: 3 | E17: 0 | F17: 家族・友人・パートナー
B18: クリスマス・年末年始 | C18: 40000 | D18: 12 | E18: 0
B19: お中元・お歳暮 | C19: 20000 | D19: 7 | E19: 0
B20: 美容（ヘア・ネイル） | C20: 60000 | E20: 0
B21: 推し活・イベント | C21: 50000 | D21: 10 | E21: 0 | F21: チケット・グッズ・遠征
B22: 家電・家具の買い替え | C22: 40000 | D22: 11 | E22: 0
B23: 資格・習い事 | C23: 30000 | D23: 4 | E23: 0
B24: 年払い（保険・サブスク） | C24: 30000 | D24: 9 | E24: 0
B25: その他（予備費） | C25: 20000 | E25: 0 | F25: 想定外の出費用
B31: ※年間予算・予定月の初期値は「例」です（出典なし・参考用）。支払予定月は空欄でもOKです。

Sheet 月別
B1: 月別の見える化
B2: すべて自動計算です（触らなくてOK）。入力シートに記録すると、ここに反映されます。
B4: ① 実際に使った額（月別）
B5: 項目 | C5: =DATE(設定!$C$5,設定!$C$6,1) -> 46023 | D5: =DATE(YEAR(C5),MONTH(C5)+1,1) -> 46054 | E5: =DATE(YEAR(D5),MONTH(D5)+1,1) -> 46082 | F5: =DATE(YEAR(E5),MONTH(E5)+1,1) -> 46113 | G5: =DATE(YEAR(F5),MONTH(F5)+1,1) -> 46143 | H5: =DATE(YEAR(G5),MONTH(G5)+1,1) -> 46174 | I5: =DATE(YEAR(H5),MONTH(H5)+1,1) -> 46204 | J5: =DATE(YEAR(I5),MONTH(I5)+1,1) -> 46235 | K5: =DATE(YEAR(J5),MONTH(J5)+1,1) -> 46266 | ... N5: =DATE(YEAR(M5),MONTH(M5)+1,1) -> 46357 | O5: 合計
B6: =IF(設定!B15="","",設定!B15) -> 帰省・旅行 | C6: =IF($B6="","",SUMIFS(入力!$C$5:$C$1004,入力!$B$5:$B$1004,$B6,入力!$A$5:$A$1004,">="&C$5,入力!$A$5:$A$1004,"<"&DATE(YEAR(C$5),MONTH(C$5)+1,1))) -> 0 | D6: =IF($B6="","",SUMIFS(入力!$C$5:$C$1004,入力!$B$5:$B$1004,$B6,入力!$A$5:$A$1004,">="&D$5,入力!$A$5:$A$1004,"<"&DATE(YEAR(D$5),MONTH(D$5)+1,1))) -> 0 | E6: =IF($B6="","",SUMIFS(入力!$C$5:$C$1004,入力!$B$5:$B$1004,$B6,入力!$A$5:$A$1004,">="&E$5,入力!$A$5:$A$1004,"<"&DATE(YEAR(E$5),MONTH(E$5)+1,1))) -> 0 | F6: =IF($B6="","",SUMIFS(入力!$C$5:$C$1004,入力!$B$5:$B$1004,$B6,入力!$A$5:$A$1004,">="&F$5,入力!$A$5:$A$1004,"<"&DATE(YEAR(F$5),MONTH(F$5)+1,1))) -> 0 | G6: =IF($B6="","",SUMIFS(入力!$C$5:$C$1004,入力!$B$5:$B$1004,$B6,入力!$A$5:$A$1004,">="&G$5,入力!$A$5:$A$1004,"<"&DATE(YEAR(G$5),MONTH(G$5)+1,1))) -> 0 | H6: =IF($B6="","",SUMIFS(入力!$C$5:$C$1004,入力!$B$5:$B$1004,$B6,入力!$A$5:$A$1004,">="&H$5,入力!$A$5:$A$1004,"<"&DATE(YEAR(H$5),MONTH(H$5)+1,1))) -> 0 | I6: =IF($B6="","",SUMIFS(入力!$C$5:$C$1004,入力!$B$5:$B$1004,$B6,入力!$A$5:$A$1004,">="&I$5,入力!$A$5:$A$1004,"<"&DATE(YEAR(I$5),MONTH(I$5)+1,1))) -> 0 | J6: =IF($B6="","",SUMIFS(入力!$C$5:$C$1004,入力!$B$5:$B$1004,$B6,入力!$A$5:$A$1004,">="&J$5,入力!$A$5:$A$1004,"<"&DATE(YEAR(J$5),MONTH(J$5)+1,1))) -> 0 | ... N6: =IF($B6="","",SUMIFS(入力!$C$5:$C$1004,入力!$B$5:$B$1004,$B6,入力!$A$5:$A$1004,">="&N$5,入力!$A$5:$A$1004,"<"&DATE(YEAR(N$5),MONTH(N$5)+1,1))) -> 0 | O6: =IF($B6="","",SUM(C6:N6)) -> 0
B7: =IF(設定!B16="","",設定!B16) -> 冠婚葬祭（ご祝儀・香典） | C7: =IF($B7="","",SUMIFS(入力!$C$5:$C$1004,入力!$B$5:$B$1004,$B7,入力!$A$5:$A$1004,">="&C$5,入力!$A$5:$A$1004,"<"&DATE(YEAR(C$5),MONTH(C$5)+1,1))) -> 0 | D7: =IF($B7="","",SUMIFS(入力!$C$5:$C$1004,入力!$B$5:$B$1004,$B7,入力!$A$5:$A$1004,">="&D$5,入力!$A$5:$A$1004,"<"&DATE(YEAR(D$5),MONTH(D$5)+1,1))) -> 0 | E7: =IF($B7="","",SUMIFS(入力!$C$5:$C$1004,入力!$B$5:$B$1004,$B7,入力!$A$5:$A$1004,">="&E$5,入力!$A$5:$A$1004,"<"&DATE(YEAR(E$5),MONTH(E$5)+1,1))) -> 0 | F7: =IF($B7="","",SUMIFS(入力!$C$5:$C$1004,入力!$B$5:$B$1004,$B7,入力!$A$5:$A$1004,">="&F$5,入力!$A$5:$A$1004,"<"&DATE(YEAR(F$5),MONTH(F$5)+1,1))) -> 0 | G7: =IF($B7="","",SUMIFS(入力!$C$5:$C$1004,入力!$B$5:$B$1004,$B7,入力!$A$5:$A$1004,">="&G$5,入力!$A$5:$A$1004,"<"&DATE(YEAR(G$5),MONTH(G$5)+1,1))) -> 0 | H7: =IF($B7="","",SUMIFS(入力!$C$5:$C$1004,入力!$B$5:$B$1004,$B7,入力!$A$5:$A$1004,">="&H$5,入力!$A$5:$A$1004,"<"&DATE(YEAR(H$5),MONTH(H$5)+1,1))) -> 0 | I7: =IF($B7="","",SUMIFS(入力!$C$5:$C$1004,入力!$B$5:$B$1004,$B7,入力!$A$5:$A$1004,">="&I$5,入力!$A$5:$A$1004,"<"&DATE(YEAR(I$5),MONTH(I$5)+1,1))) -> 0 | J7: =IF($B7="","",SUMIFS(入力!$C$5:$C$1004,入力!$B$5:$B$1004,$B7,入力!$A$5:$A$1004,">="&J$5,入力!$A$5:$A$1004,"<"&DATE(YEAR(J$5),MONTH(J$5)+1,1))) -> 0 | ... N7: =IF($B7="","",SUMIFS(入力!$C$5:$C$1004,入力!$B$5:$B$1004,$B7,入力!$A$5:$A$1004,">="&N$5,入力!$A$5:$A$1004,"<"&DATE(YEAR(N$5),MONTH(N$5)+1,1))) -> 0 | O7: =IF($B7="","",SUM(C7:N7)) -> 0
B8: =IF(設定!B17="","",設定!B17) -> 誕生日・記念日 | C8: =IF($B8="","",SUMIFS(入力!$C$5:$C$1004,入力!$B$5:$B$1004,$B8,入力!$A$5:$A$1004,">="&C$5,入力!$A$5:$A$1004,"<"&DATE(YEAR(C$5),MONTH(C$5)+1,1))) -> 0 | D8: =IF($B8="","",SUMIFS(入力!$C$5:$C$1004,入力!$B$5:$B$1004,$B8,入力!$A$5:$A$1004,">="&D$5,入力!$A$5:$A$1004,"<"&DATE(YEAR(D$5),MONTH(D$5)+1,1))) -> 0 | E8: =IF($B8="","",SUMIFS(入力!$C$5:$C$1004,入力!$B$5:$B$1004,$B8,入力!$A$5:$A$1004,">="&E$5,入力!$A$5:$A$1004,"<"&DATE(YEAR(E$5),MONTH(E$5)+1,1))) -> 0 | F8: =IF($B8="","",SUMIFS(入力!$C$5:$C$1004,入力!$B$5:$B$1004,$B8,入力!$A$5:$A$1004,">="&F$5,入力!$A$5:$A$1004,"<"&DATE(YEAR(F$5),MONTH(F$5)+1,1))) -> 0 | G8: =IF($B8="","",SUMIFS(入力!$C$5:$C$1004,入力!$B$5:$B$1004,$B8,入力!$A$5:$A$1004,">="&G$5,入力!$A$5:$A$1004,"<"&DATE(YEAR(G$5),MONTH(G$5)+1,1))) -> 0 | H8: =IF($B8="","",SUMIFS(入力!$C$5:$C$1004,入力!$B$5:$B$1004,$B8,入力!$A$5:$A$1004,">="&H$5,入力!$A$5:$A$1004,"<"&DATE(YEAR(H$5),MONTH(H$5)+1,1))) -> 0 | I8: =IF($B8="","",SUMIFS(入力!$C$5:$C$1004,入力!$B$5:$B$1004,$B8,入力!$A$5:$A$1004,">="&I$5,入力!$A$5:$A$1004,"<"&DATE(YEAR(I$5),MONTH(I$5)+1,1))) -> 0 | J8: =IF($B8="","",SUMIFS(入力!$C$5:$C$1004,入力!$B$5:$B$1004,$B8,入力!$A$5:$A$1004,">="&J$5,入力!$A$5:$A$1004,"<"&DATE(YEAR(J$5),MONTH(J$5)+1,1))) -> 0 | ... N8: =IF($B8="","",SUMIFS(入力!$C$5:$C$1004,入力!$B$5:$B$1004,$B8,入力!$A$5:$A$1004,">="&N$5,入力!$A$5:$A$1004,"<"&DATE(YEAR(N$5),MONTH(N$5)+1,1))) -> 0 | O8: =IF($B8="","",SUM(C8:N8)) -> 0
B9: =IF(設定!B18="","",設定!B18) -> クリスマス・年末年始 | C9: =IF($B9="","",SUMIFS(入力!$C$5:$C$1004,入力!$B$5:$B$1004,$B9,入力!$A$5:$A$1004,">="&C$5,入力!$A$5:$A$1004,"<"&DATE(YEAR(C$5),MONTH(C$5)+1,1))) -> 0 | D9: =IF($B9="","",SUMIFS(入力!$C$5:$C$1004,入力!$B$5:$B$1004,$B9,入力!$A$5:$A$1004,">="&D$5,入力!$A$5:$A$1004,"<"&DATE(YEAR(D$5),MONTH(D$5)+1,1))) -> 0 | E9: =IF($B9="","",SUMIFS(入力!$C$5:$C$1004,入力!$B$5:$B$1004,$B9,入力!$A$5:$A$1004,">="&E$5,入力!$A$5:$A$1004,"<"&DATE(YEAR(E$5),MONTH(E$5)+1,1))) -> 0 | F9: =IF($B9="","",SUMIFS(入力!$C$5:$C$1004,入力!$B$5:$B$1004,$B9,入力!$A$5:$A$1004,">="&F$5,入力!$A$5:$A$1004,"<"&DATE(YEAR(F$5),MONTH(F$5)+1,1))) -> 0 | G9: =IF($B9="","",SUMIFS(入力!$C$5:$C$1004,入力!$B$5:$B$1004,$B9,入力!$A$5:$A$1004,">="&G$5,入力!$A$5:$A$1004,"<"&DATE(YEAR(G$5),MONTH(G$5)+1,1))) -> 0 | H9: =IF($B9="","",SUMIFS(入力!$C$5:$C$1004,入力!$B$5:$B$1004,$B9,入力!$A$5:$A$1004,">="&H$5,入力!$A$5:$A$1004,"<"&DATE(YEAR(H$5),MONTH(H$5)+1,1))) -> 0 | I9: =IF($B9="","",SUMIFS(入力!$C$5:$C$1004,入力!$B$5:$B$1004,$B9,入力!$A$5:$A$1004,">="&I$5,入力!$A$5:$A$1004,"<"&DATE(YEAR(I$5),MONTH(I$5)+1,1))) -> 0 | J9: =IF($B9="","",SUMIFS(入力!$C$5:$C$1004,入力!$B$5:$B$1004,$B9,入力!$A$5:$A$1004,">="&J$5,入力!$A$5:$A$1004,"<"&DATE(YEAR(J$5),MONTH(J$5)+1,1))) -> 0 | ... N9: =IF($B9="","",SUMIFS(入力!$C$5:$C$1004,入力!$B$5:$B$1004,$B9,入力!$A$5:$A$1004,">="&N$5,入力!$A$5:$A$1004,"<"&DATE(YEAR(N$5),MONTH(N$5)+1,1))) -> 0 | O9: =IF($B9="","",SUM(C9:N9)) -> 0
B10: =IF(設定!B19="","",設定!B19) -> お中元・お歳暮 | C10: =IF($B10="","",SUMIFS(入力!$C$5:$C$1004,入力!$B$5:$B$1004,$B10,入力!$A$5:$A$1004,">="&C$5,入力!$A$5:$A$1004,"<"&DATE(YEAR(C$5),MONTH(C$5)+1,1))) -> 0 | D10: =IF($B10="","",SUMIFS(入力!$C$5:$C$1004,入力!$B$5:$B$1004,$B10,入力!$A$5:$A$1004,">="&D$5,入力!$A$5:$A$1004,"<"&DATE(YEAR(D$5),MONTH(D$5)+1,1))) -> 0 | E10: =IF($B10="","",SUMIFS(入力!$C$5:$C$1004,入力!$B$5:$B$1004,$B10,入力!$A$5:$A$1004,">="&E$5,入力!$A$5:$A$1004,"<"&DATE(YEAR(E$5),MONTH(E$5)+1,1))) -> 0 | F10: =IF($B10="","",SUMIFS(入力!$C$5:$C$1004,入力!$B$5:$B$1004,$B10,入力!$A$5:$A$1004,">="&F$5,入力!$A$5:$A$1004,"<"&DATE(YEAR(F$5),MONTH(F$5)+1,1))) -> 0 | G10: =IF($B10="","",SUMIFS(入力!$C$5:$C$1004,入力!$B$5:$B$1004,$B10,入力!$A$5:$A$1004,">="&G$5,入力!$A$5:$A$1004,"<"&DATE(YEAR(G$5),MONTH(G$5)+1,1))) -> 0 | H10: =IF($B10="","",SUMIFS(入力!$C$5:$C$1004,入力!$B$5:$B$1004,$B10,入力!$A$5:$A$1004,">="&H$5,入力!$A$5:$A$1004,"<"&DATE(YEAR(H$5),MONTH(H$5)+1,1))) -> 0 | I10: =IF($B10="","",SUMIFS(入力!$C$5:$C$1004,入力!$B$5:$B$1004,$B10,入力!$A$5:$A$1004,">="&I$5,入力!$A$5:$A$1004,"<"&DATE(YEAR(I$5),MONTH(I$5)+1,1))) -> 0 | J10: =IF($B10="","",SUMIFS(入力!$C$5:$C$1004,入力!$B$5:$B$1004,$B10,入力!$A$5:$A$1004,">="&J$5,入力!$A$5:$A$1004,"<"&DATE(YEAR(J$5),MONTH(J$5)+1,1))) -> 0 | ... N10: =IF($B10="","",SUMIFS(入力!$C$5:$C$1004,入力!$B$5:$B$1004,$B10,入力!$A$5:$A$1004,">="&N$5,入力!$A$5:$A$1004,"<"&DATE(YEAR(N$5),MONTH(N$5)+1,1))) -> 0 | O10: =IF($B10="","",SUM(C10:N10)) -> 0
B11: =IF(設定!B20="","",設定!B20) -> 美容（ヘア・ネイル） | C11: =IF($B11="","",SUMIFS(入力!$C$5:$C$1004,入力!$B$5:$B$1004,$B11,入力!$A$5:$A$1004,">="&C$5,入力!$A$5:$A$1004,"<"&DATE(YEAR(C$5),MONTH(C$5)+1,1))) -> 0 | D11: =IF($B11="","",SUMIFS(入力!$C$5:$C$1004,入力!$B$5:$B$1004,$B11,入力!$A$5:$A$1004,">="&D$5,入力!$A$5:$A$1004,"<"&DATE(YEAR(D$5),MONTH(D$5)+1,1))) -> 0 | E11: =IF($B11="","",SUMIFS(入力!$C$5:$C$1004,入力!$B$5:$B$1004,$B11,入力!$A$5:$A$1004,">="&E$5,入力!$A$5:$A$1004,"<"&DATE(YEAR(E$5),MONTH(E$5)+1,1))) -> 0 | F11: =IF($B11="","",SUMIFS(入力!$C$5:$C$1004,入力!$B$5:$B$1004,$B11,入力!$A$5:$A$1004,">="&F$5,入力!$A$5:$A$1004,"<"&DATE(YEAR(F$5),MONTH(F$5)+1,1))) -> 0 | G11: =IF($B11="","",SUMIFS(入力!$C$5:$C$1004,入力!$B$5:$B$1004,$B11,入力!$A$5:$A$1004,">="&G$5,入力!$A$5:$A$1004,"<"&DATE(YEAR(G$5),MONTH(G$5)+1,1))) -> 0 | H11: =IF($B11="","",SUMIFS(入力!$C$5:$C$1004,入力!$B$5:$B$1004,$B11,入力!$A$5:$A$1004,">="&H$5,入力!$A$5:$A$1004,"<"&DATE(YEAR(H$5),MONTH(H$5)+1,1))) -> 0 | I11: =IF($B11="","",SUMIFS(入力!$C$5:$C$1004,入力!$B$5:$B$1004,$B11,入力!$A$5:$A$1004,">="&I$5,入力!$A$5:$A$1004,"<"&DATE(YEAR(I$5),MONTH(I$5)+1,1))) -> 0 | J11: =IF($B11="","",SUMIFS(入力!$C$5:$C$1004,入力!$B$5:$B$1004,$B11,入力!$A$5:$A$1004,">="&J$5,入力!$A$5:$A$1004,"<"&DATE(YEAR(J$5),MONTH(J$5)+1,1))) -> 0 | ... N11: =IF($B11="","",SUMIFS(入力!$C$5:$C$1004,入力!$B$5:$B$1004,$B11,入力!$A$5:$A$1004,">="&N$5,入力!$A$5:$A$1004,"<"&DATE(YEAR(N$5),MONTH(N$5)+1,1))) -> 0 | O11: =IF($B11="","",SUM(C11:N11)) -> 0
B12: =IF(設定!B21="","",設定!B21) -> 推し活・イベント | C12: =IF($B12="","",SUMIFS(入力!$C$5:$C$1004,入力!$B$5:$B$1004,$B12,入力!$A$5:$A$1004,">="&C$5,入力!$A$5:$A$1004,"<"&DATE(YEAR(C$5),MONTH(C$5)+1,1))) -> 0 | D12: =IF($B12="","",SUMIFS(入力!$C$5:$C$1004,入力!$B$5:$B$1004,$B12,入力!$A$5:$A$1004,">="&D$5,入力!$A$5:$A$1004,"<"&DATE(YEAR(D$5),MONTH(D$5)+1,1))) -> 0 | E12: =IF($B12="","",SUMIFS(入力!$C$5:$C$1004,入力!$B$5:$B$1004,$B12,入力!$A$5:$A$1004,">="&E$5,入力!$A$5:$A$1004,"<"&DATE(YEAR(E$5),MONTH(E$5)+1,1))) -> 0 | F12: =IF($B12="","",SUMIFS(入力!$C$5:$C$1004,入力!$B$5:$B$1004,$B12,入力!$A$5:$A$1004,">="&F$5,入力!$A$5:$A$1004,"<"&DATE(YEAR(F$5),MONTH(F$5)+1,1))) -> 0 | G12: =IF($B12="","",SUMIFS(入力!$C$5:$C$1004,入力!$B$5:$B$1004,$B12,入力!$A$5:$A$1004,">="&G$5,入力!$A$5:$A$1004,"<"&DATE(YEAR(G$5),MONTH(G$5)+1,1))) -> 0 | H12: =IF($B12="","",SUMIFS(入力!$C$5:$C$1004,入力!$B$5:$B$1004,$B12,入力!$A$5:$A$1004,">="&H$5,入力!$A$5:$A$1004,"<"&DATE(YEAR(H$5),MONTH(H$5)+1,1))) -> 0 | I12: =IF($B12="","",SUMIFS(入力!$C$5:$C$1004,入力!$B$5:$B$1004,$B12,入力!$A$5:$A$1004,">="&I$5,入力!$A$5:$A$1004,"<"&DATE(YEAR(I$5),MONTH(I$5)+1,1))) -> 0 | J12: =IF($B12="","",SUMIFS(入力!$C$5:$C$1004,入力!$B$5:$B$1004,$B12,入力!$A$5:$A$1004,">="&J$5,入力!$A$5:$A$1004,"<"&DATE(YEAR(J$5),MONTH(J$5)+1,1))) -> 0 | ... N12: =IF($B12="","",SUMIFS(入力!$C$5:$C$1004,入力!$B$5:$B$1004,$B12,入力!$A$5:$A$1004,">="&N$5,入力!$A$5:$A$1004,"<"&DATE(YEAR(N$5),MONTH(N$5)+1,1))) -> 0 | O12: =IF($B12="","",SUM(C12:N12)) -> 0
B13: =IF(設定!B22="","",設定!B22) -> 家電・家具の買い替え | C13: =IF($B13="","",SUMIFS(入力!$C$5:$C$1004,入力!$B$5:$B$1004,$B13,入力!$A$5:$A$1004,">="&C$5,入力!$A$5:$A$1004,"<"&DATE(YEAR(C$5),MONTH(C$5)+1,1))) -> 0 | D13: =IF($B13="","",SUMIFS(入力!$C$5:$C$1004,入力!$B$5:$B$1004,$B13,入力!$A$5:$A$1004,">="&D$5,入力!$A$5:$A$1004,"<"&DATE(YEAR(D$5),MONTH(D$5)+1,1))) -> 0 | E13: =IF($B13="","",SUMIFS(入力!$C$5:$C$1004,入力!$B$5:$B$1004,$B13,入力!$A$5:$A$1004,">="&E$5,入力!$A$5:$A$1004,"<"&DATE(YEAR(E$5),MONTH(E$5)+1,1))) -> 0 | F13: =IF($B13="","",SUMIFS(入力!$C$5:$C$1004,入力!$B$5:$B$1004,$B13,入力!$A$5:$A$1004,">="&F$5,入力!$A$5:$A$1004,"<"&DATE(YEAR(F$5),MONTH(F$5)+1,1))) -> 0 | G13: =IF($B13="","",SUMIFS(入力!$C$5:$C$1004,入力!$B$5:$B$1004,$B13,入力!$A$5:$A$1004,">="&G$5,入力!$A$5:$A$1004,"<"&DATE(YEAR(G$5),MONTH(G$5)+1,1))) -> 0 | H13: =IF($B13="","",SUMIFS(入力!$C$5:$C$1004,入力!$B$5:$B$1004,$B13,入力!$A$5:$A$1004,">="&H$5,入力!$A$5:$A$1004,"<"&DATE(YEAR(H$5),MONTH(H$5)+1,1))) -> 0 | I13: =IF($B13="","",SUMIFS(入力!$C$5:$C$1004,入力!$B$5:$B$1004,$B13,入力!$A$5:$A$1004,">="&I$5,入力!$A$5:$A$1004,"<"&DATE(YEAR(I$5),MONTH(I$5)+1,1))) -> 0 | J13: =IF($B13="","",SUMIFS(入力!$C$5:$C$1004,入力!$B$5:$B$1004,$B13,入力!$A$5:$A$1004,">="&J$5,入力!$A$5:$A$1004,"<"&DATE(YEAR(J$5),MONTH(J$5)+1,1))) -> 0 | ... N13: =IF($B13="","",SUMIFS(入力!$C$5:$C$1004,入力!$B$5:$B$1004,$B13,入力!$A$5:$A$1004,">="&N$5,入力!$A$5:$A$1004,"<"&DATE(YEAR(N$5),MONTH(N$5)+1,1))) -> 0 | O13: =IF($B13="","",SUM(C13:N13)) -> 0
B14: =IF(設定!B23="","",設定!B23) -> 資格・習い事 | C14: =IF($B14="","",SUMIFS(入力!$C$5:$C$1004,入力!$B$5:$B$1004,$B14,入力!$A$5:$A$1004,">="&C$5,入力!$A$5:$A$1004,"<"&DATE(YEAR(C$5),MONTH(C$5)+1,1))) -> 0 | D14: =IF($B14="","",SUMIFS(入力!$C$5:$C$1004,入力!$B$5:$B$1004,$B14,入力!$A$5:$A$1004,">="&D$5,入力!$A$5:$A$1004,"<"&DATE(YEAR(D$5),MONTH(D$5)+1,1))) -> 0 | E14: =IF($B14="","",SUMIFS(入力!$C$5:$C$1004,入力!$B$5:$B$1004,$B14,入力!$A$5:$A$1004,">="&E$5,入力!$A$5:$A$1004,"<"&DATE(YEAR(E$5),MONTH(E$5)+1,1))) -> 0 | F14: =IF($B14="","",SUMIFS(入力!$C$5:$C$1004,入力!$B$5:$B$1004,$B14,入力!$A$5:$A$1004,">="&F$5,入力!$A$5:$A$1004,"<"&DATE(YEAR(F$5),MONTH(F$5)+1,1))) -> 0 | G14: =IF($B14="","",SUMIFS(入力!$C$5:$C$1004,入力!$B$5:$B$1004,$B14,入力!$A$5:$A$1004,">="&G$5,入力!$A$5:$A$1004,"<"&DATE(YEAR(G$5),MONTH(G$5)+1,1))) -> 0 | H14: =IF($B14="","",SUMIFS(入力!$C$5:$C$1004,入力!$B$5:$B$1004,$B14,入力!$A$5:$A$1004,">="&H$5,入力!$A$5:$A$1004,"<"&DATE(YEAR(H$5),MONTH(H$5)+1,1))) -> 0 | I14: =IF($B14="","",SUMIFS(入力!$C$5:$C$1004,入力!$B$5:$B$1004,$B14,入力!$A$5:$A$1004,">="&I$5,入力!$A$5:$A$1004,"<"&DATE(YEAR(I$5),MONTH(I$5)+1,1))) -> 0 | J14: =IF($B14="","",SUMIFS(入力!$C$5:$C$1004,入力!$B$5:$B$1004,$B14,入力!$A$5:$A$1004,">="&J$5,入力!$A$5:$A$1004,"<"&DATE(YEAR(J$5),MONTH(J$5)+1,1))) -> 0 | ... N14: =IF($B14="","",SUMIFS(入力!$C$5:$C$1004,入力!$B$5:$B$1004,$B14,入力!$A$5:$A$1004,">="&N$5,入力!$A$5:$A$1004,"<"&DATE(YEAR(N$5),MONTH(N$5)+1,1))) -> 0 | O14: =IF($B14="","",SUM(C14:N14)) -> 0
B15: =IF(設定!B24="","",設定!B24) -> 年払い（保険・サブスク） | C15: =IF($B15="","",SUMIFS(入力!$C$5:$C$1004,入力!$B$5:$B$1004,$B15,入力!$A$5:$A$1004,">="&C$5,入力!$A$5:$A$1004,"<"&DATE(YEAR(C$5),MONTH(C$5)+1,1))) -> 0 | D15: =IF($B15="","",SUMIFS(入力!$C$5:$C$1004,入力!$B$5:$B$1004,$B15,入力!$A$5:$A$1004,">="&D$5,入力!$A$5:$A$1004,"<"&DATE(YEAR(D$5),MONTH(D$5)+1,1))) -> 0 | E15: =IF($B15="","",SUMIFS(入力!$C$5:$C$1004,入力!$B$5:$B$1004,$B15,入力!$A$5:$A$1004,">="&E$5,入力!$A$5:$A$1004,"<"&DATE(YEAR(E$5),MONTH(E$5)+1,1))) -> 0 | F15: =IF($B15="","",SUMIFS(入力!$C$5:$C$1004,入力!$B$5:$B$1004,$B15,入力!$A$5:$A$1004,">="&F$5,入力!$A$5:$A$1004,"<"&DATE(YEAR(F$5),MONTH(F$5)+1,1))) -> 0 | G15: =IF($B15="","",SUMIFS(入力!$C$5:$C$1004,入力!$B$5:$B$1004,$B15,入力!$A$5:$A$1004,">="&G$5,入力!$A$5:$A$1004,"<"&DATE(YEAR(G$5),MONTH(G$5)+1,1))) -> 0 | H15: =IF($B15="","",SUMIFS(入力!$C$5:$C$1004,入力!$B$5:$B$1004,$B15,入力!$A$5:$A$1004,">="&H$5,入力!$A$5:$A$1004,"<"&DATE(YEAR(H$5),MONTH(H$5)+1,1))) -> 0 | I15: =IF($B15="","",SUMIFS(入力!$C$5:$C$1004,入力!$B$5:$B$1004,$B15,入力!$A$5:$A$1004,">="&I$5,入力!$A$5:$A$1004,"<"&DATE(YEAR(I$5),MONTH(I$5)+1,1))) -> 0 | J15: =IF($B15="","",SUMIFS(入力!$C$5:$C$1004,入力!$B$5:$B$1004,$B15,入力!$A$5:$A$1004,">="&J$5,入力!$A$5:$A$1004,"<"&DATE(YEAR(J$5),MONTH(J$5)+1,1))) -> 0 | ... N15: =IF($B15="","",SUMIFS(入力!$C$5:$C$1004,入力!$B$5:$B$1004,$B15,入力!$A$5:$A$1004,">="&N$5,入力!$A$5:$A$1004,"<"&DATE(YEAR(N$5),MONTH(N$5)+1,1))) -> 0 | O15: =IF($B15="","",SUM(C15:N15)) -> 0
B16: =IF(設定!B25="","",設定!B25) -> その他（予備費） | C16: =IF($B16="","",SUMIFS(入力!$C$5:$C$1004,入力!$B$5:$B$1004,$B16,入力!$A$5:$A$1004,">="&C$5,入力!$A$5:$A$1004,"<"&DATE(YEAR(C$5),MONTH(C$5)+1,1))) -> 0 | D16: =IF($B16="","",SUMIFS(入力!$C$5:$C$1004,入力!$B$5:$B$1004,$B16,入力!$A$5:$A$1004,">="&D$5,入力!$A$5:$A$1004,"<"&DATE(YEAR(D$5),MONTH(D$5)+1,1))) -> 0 | E16: =IF($B16="","",SUMIFS(入力!$C$5:$C$1004,入力!$B$5:$B$1004,$B16,入力!$A$5:$A$1004,">="&E$5,入力!$A$5:$A$1004,"<"&DATE(YEAR(E$5),MONTH(E$5)+1,1))) -> 0 | F16: =IF($B16="","",SUMIFS(入力!$C$5:$C$1004,入力!$B$5:$B$1004,$B16,入力!$A$5:$A$1004,">="&F$5,入力!$A$5:$A$1004,"<"&DATE(YEAR(F$5),MONTH(F$5)+1,1))) -> 0 | G16: =IF($B16="","",SUMIFS(入力!$C$5:$C$1004,入力!$B$5:$B$1004,$B16,入力!$A$5:$A$1004,">="&G$5,入力!$A$5:$A$1004,"<"&DATE(YEAR(G$5),MONTH(G$5)+1,1))) -> 0 | H16: =IF($B16="","",SUMIFS(入力!$C$5:$C$1004,入力!$B$5:$B$1004,$B16,入力!$A$5:$A$1004,">="&H$5,入力!$A$5:$A$1004,"<"&DATE(YEAR(H$5),MONTH(H$5)+1,1))) -> 0 | I16: =IF($B16="","",SUMIFS(入力!$C$5:$C$1004,入力!$B$5:$B$1004,$B16,入力!$A$5:$A$1004,">="&I$5,入力!$A$5:$A$1004,"<"&DATE(YEAR(I$5),MONTH(I$5)+1,1))) -> 0 | J16: =IF($B16="","",SUMIFS(入力!$C$5:$C$1004,入力!$B$5:$B$1004,$B16,入力!$A$5:$A$1004,">="&J$5,入力!$A$5:$A$1004,"<"&DATE(YEAR(J$5),MONTH(J$5)+1,1))) -> 0 | ... N16: =IF($B16="","",SUMIFS(入力!$C$5:$C$1004,入力!$B$5:$B$1004,$B16,入力!$A$5:$A$1004,">="&N$5,入力!$A$5:$A$1004,"<"&DATE(YEAR(N$5),MONTH(N$5)+1,1))) -> 0 | O16: =IF($B16="","",SUM(C16:N16)) -> 0
B17: =IF(設定!B26="","",設定!B26) | C17: =IF($B17="","",SUMIFS(入力!$C$5:$C$1004,入力!$B$5:$B$1004,$B17,入力!$A$5:$A$1004,">="&C$5,入力!$A$5:$A$1004,"<"&DATE(YEAR(C$5),MONTH(C$5)+1,1))) | D17: =IF($B17="","",SUMIFS(入力!$C$5:$C$1004,入力!$B$5:$B$1004,$B17,入力!$A$5:$A$1004,">="&D$5,入力!$A$5:$A$1004,"<"&DATE(YEAR(D$5),MONTH(D$5)+1,1))) | E17: =IF($B17="","",SUMIFS(入力!$C$5:$C$1004,入力!$B$5:$B$1004,$B17,入力!$A$5:$A$1004,">="&E$5,入力!$A$5:$A$1004,"<"&DATE(YEAR(E$5),MONTH(E$5)+1,1))) | F17: =IF($B17="","",SUMIFS(入力!$C$5:$C$1004,入力!$B$5:$B$1004,$B17,入力!$A$5:$A$1004,">="&F$5,入力!$A$5:$A$1004,"<"&DATE(YEAR(F$5),MONTH(F$5)+1,1))) | G17: =IF($B17="","",SUMIFS(入力!$C$5:$C$1004,入力!$B$5:$B$1004,$B17,入力!$A$5:$A$1004,">="&G$5,入力!$A$5:$A$1004,"<"&DATE(YEAR(G$5),MONTH(G$5)+1,1))) | H17: =IF($B17="","",SUMIFS(入力!$C$5:$C$1004,入力!$B$5:$B$1004,$B17,入力!$A$5:$A$1004,">="&H$5,入力!$A$5:$A$1004,"<"&DATE(YEAR(H$5),MONTH(H$5)+1,1))) | I17: =IF($B17="","",SUMIFS(入力!$C$5:$C$1004,入力!$B$5:$B$1004,$B17,入力!$A$5:$A$1004,">="&I$5,入力!$A$5:$A$1004,"<"&DATE(YEAR(I$5),MONTH(I$5)+1,1))) | J17: =IF($B17="","",SUMIFS(入力!$C$5:$C$1004,入力!$B$5:$B$1004,$B17,入力!$A$5:$A$1004,">="&J$5,入力!$A$5:$A$1004,"<"&DATE(YEAR(J$5),MONTH(J$5)+1,1))) | ... N17: =IF($B17="","",SUMIFS(入力!$C$5:$C$1004,入力!$B$5:$B$1004,$B17,入力!$A$5:$A$1004,">="&N$5,入力!$A$5:$A$1004,"<"&DATE(YEAR(N$5),MONTH(N$5)+1,1))) | O17: =IF($B17="","",SUM(C17:N17))
... B20: =IF(設定!B29="","",設定!B29) | C20: =IF($B20="","",SUMIFS(入力!$C$5:$C$1004,入力!$B$5:$B$1004,$B20,入力!$A$5:$A$1004,">="&C$5,入力!$A$5:$A$1004,"<"&DATE(YEAR(C$5),MONTH(C$5)+1,1))) | D20: =IF($B20="","",SUMIFS(入力!$C$5:$C$1004,入力!$B$5:$B$1004,$B20,入力!$A$5:$A$1004,">="&D$5,入力!$A$5:$A$1004,"<"&DATE(YEAR(D$5),MONTH(D$5)+1,1))) | E20: =IF($B20="","",SUMIFS(入力!$C$5:$C$1004,入力!$B$5:$B$1004,$B20,入力!$A$5:$A$1004,">="&E$5,入力!$A$5:$A$1004,"<"&DATE(YEAR(E$5),MONTH(E$5)+1,1))) | F20: =IF($B20="","",SUMIFS(入力!$C$5:$C$1004,入力!$B$5:$B$1004,$B20,入力!$A$5:$A$1004,">="&F$5,入力!$A$5:$A$1004,"<"&DATE(YEAR(F$5),MONTH(F$5)+1,1))) | G20: =IF($B20="","",SUMIFS(入力!$C$5:$C$1004,入力!$B$5:$B$1004,$B20,入力!$A$5:$A$1004,">="&G$5,入力!$A$5:$A$1004,"<"&DATE(YEAR(G$5),MONTH(G$5)+1,1))) | H20: =IF($B20="","",SUMIFS(入力!$C$5:$C$1004,入力!$B$5:$B$1004,$B20,入力!$A$5:$A$1004,">="&H$5,入力!$A$5:$A$1004,"<"&DATE(YEAR(H$5),MONTH(H$5)+1,1))) | I20: =IF($B20="","",SUMIFS(入力!$C$5:$C$1004,入力!$B$5:$B$1004,$B20,入力!$A$5:$A$1004,">="&I$5,入力!$A$5:$A$1004,"<"&DATE(YEAR(I$5),MONTH(I$5)+1,1))) | J20: =IF($B20="","",SUMIFS(入力!$C$5:$C$1004,入力!$B$5:$B$1004,$B20,入力!$A$5:$A$1004,">="&J$5,入力!$A$5:$A$1004,"<"&DATE(YEAR(J$5),MONTH(J$5)+1,1))) | ... N20: =IF($B20="","",SUMIFS(入力!$C$5:$C$1004,入力!$B$5:$B$1004,$B20,入力!$A$5:$A$1004,">="&N$5,入力!$A$5:$A$1004,"<"&DATE(YEAR(N$5),MONTH(N$5)+1,1))) | O20: =IF($B20="","",SUM(C20:N20))
B21: 合計 | C21: =SUM(C6:C20) -> 0 | D21: =SUM(D6:D20) -> 0 | E21: =SUM(E6:E20) -> 0 | F21: =SUM(F6:F20) -> 0 | G21: =SUM(G6:G20) -> 0 | H21: =SUM(H6:H20) -> 0 | I21: =SUM(I6:I20) -> 0 | J21: =SUM(J6:J20) -> 0 | ... O21: =SUM(O6:O20) -> 0
B23: ② 支払い予定（設定した「支払予定月」に年間予算を表示）
B24: 項目 | C24: =C$5 -> 46023 | D24: =D$5 -> 46054 | E24: =E$5 -> 46082 | F24: =F$5 -> 46113 | G24: =G$5 -> 46143 | H24: =H$5 -> 46174 | I24: =I$5 -> 46204 | J24: =J$5 -> 46235 | ... N24: =N$5 -> 46357 | O24: 合計
B25: =B6 -> 帰省・旅行 | C25: =IF(OR($B25="",N(設定!$D15)=0),"",IF(N(設定!$D15)=MONTH(C$24),N(設定!$C15),0)) -> 0 | D25: =IF(OR($B25="",N(設定!$D15)=0),"",IF(N(設定!$D15)=MONTH(D$24),N(設定!$C15),0)) -> 0 | E25: =IF(OR($B25="",N(設定!$D15)=0),"",IF(N(設定!$D15)=MONTH(E$24),N(設定!$C15),0)) -> 0 | F25: =IF(OR($B25="",N(設定!$D15)=0),"",IF(N(設定!$D15)=MONTH(F$24),N(設定!$C15),0)) -> 0 | G25: =IF(OR($B25="",N(設定!$D15)=0),"",IF(N(設定!$D15)=MONTH(G$24),N(設定!$C15),0)) -> 0 | H25: =IF(OR($B25="",N(設定!$D15)=0),"",IF(N(設定!$D15)=MONTH(H$24),N(設定!$C15),0)) -> 0 | I25: =IF(OR($B25="",N(設定!$D15)=0),"",IF(N(設定!$D15)=MONTH(I$24),N(設定!$C15),0)) -> 0 | J25: =IF(OR($B25="",N(設定!$D15)=0),"",IF(N(設定!$D15)=MONTH(J$24),N(設定!$C15),0)) -> 80000 | ... N25: =IF(OR($B25="",N(設定!$D15)=0),"",IF(N(設定!$D15)=MONTH(N$24),N(設定!$C15),0)) -> 0 | O25: =IF($B25="","",SUM(C25:N25)) -> 80000
B26: =B7 -> 冠婚葬祭（ご祝儀・香典） | C26: =IF(OR($B26="",N(設定!$D16)=0),"",IF(N(設定!$D16)=MONTH(C$24),N(設定!$C16),0)) -> 0 | D26: =IF(OR($B26="",N(設定!$D16)=0),"",IF(N(設定!$D16)=MONTH(D$24),N(設定!$C16),0)) -> 0 | E26: =IF(OR($B26="",N(設定!$D16)=0),"",IF(N(設定!$D16)=MONTH(E$24),N(設定!$C16),0)) -> 0 | F26: =IF(OR($B26="",N(設定!$D16)=0),"",IF(N(設定!$D16)=MONTH(F$24),N(設定!$C16),0)) -> 0 | G26: =IF(OR($B26="",N(設定!$D16)=0),"",IF(N(設定!$D16)=MONTH(G$24),N(設定!$C16),0)) -> 0 | H26: =IF(OR($B26="",N(設定!$D16)=0),"",IF(N(設定!$D16)=MONTH(H$24),N(設定!$C16),0)) -> 60000 | I26: =IF(OR($B26="",N(設定!$D16)=0),"",IF(N(設定!$D16)=MONTH(I$24),N(設定!$C16),0)) -> 0 | J26: =IF(OR($B26="",N(設定!$D16)=0),"",IF(N(設定!$D16)=MONTH(J$24),N(設定!$C16),0)) -> 0 | ... N26: =IF(OR($B26="",N(設定!$D16)=0),"",IF(N(設定!$D16)=MONTH(N$24),N(設定!$C16),0)) -> 0 | O26: =IF($B26="","",SUM(C26:N26)) -> 60000
B27: =B8 -> 誕生日・記念日 | C27: =IF(OR($B27="",N(設定!$D17)=0),"",IF(N(設定!$D17)=MONTH(C$24),N(設定!$C17),0)) -> 0 | D27: =IF(OR($B27="",N(設定!$D17)=0),"",IF(N(設定!$D17)=MONTH(D$24),N(設定!$C17),0)) -> 0 | E27: =IF(OR($B27="",N(設定!$D17)=0),"",IF(N(設定!$D17)=MONTH(E$24),N(設定!$C17),0)) -> 30000 | F27: =IF(OR($B27="",N(設定!$D17)=0),"",IF(N(設定!$D17)=MONTH(F$24),N(設定!$C17),0)) -> 0 | G27: =IF(OR($B27="",N(設定!$D17)=0),"",IF(N(設定!$D17)=MONTH(G$24),N(設定!$C17),0)) -> 0 | H27: =IF(OR($B27="",N(設定!$D17)=0),"",IF(N(設定!$D17)=MONTH(H$24),N(設定!$C17),0)) -> 0 | I27: =IF(OR($B27="",N(設定!$D17)=0),"",IF(N(設定!$D17)=MONTH(I$24),N(設定!$C17),0)) -> 0 | J27: =IF(OR($B27="",N(設定!$D17)=0),"",IF(N(設定!$D17)=MONTH(J$24),N(設定!$C17),0)) -> 0 | ... N27: =IF(OR($B27="",N(設定!$D17)=0),"",IF(N(設定!$D17)=MONTH(N$24),N(設定!$C17),0)) -> 0 | O27: =IF($B27="","",SUM(C27:N27)) -> 30000
B28: =B9 -> クリスマス・年末年始 | C28: =IF(OR($B28="",N(設定!$D18)=0),"",IF(N(設定!$D18)=MONTH(C$24),N(設定!$C18),0)) -> 0 | D28: =IF(OR($B28="",N(設定!$D18)=0),"",IF(N(設定!$D18)=MONTH(D$24),N(設定!$C18),0)) -> 0 | E28: =IF(OR($B28="",N(設定!$D18)=0),"",IF(N(設定!$D18)=MONTH(E$24),N(設定!$C18),0)) -> 0 | F28: =IF(OR($B28="",N(設定!$D18)=0),"",IF(N(設定!$D18)=MONTH(F$24),N(設定!$C18),0)) -> 0 | G28: =IF(OR($B28="",N(設定!$D18)=0),"",IF(N(設定!$D18)=MONTH(G$24),N(設定!$C18),0)) -> 0 | H28: =IF(OR($B28="",N(設定!$D18)=0),"",IF(N(設定!$D18)=MONTH(H$24),N(設定!$C18),0)) -> 0 | I28: =IF(OR($B28="",N(設定!$D18)=0),"",IF(N(設定!$D18)=MONTH(I$24),N(設定!$C18),0)) -> 0 | J28: =IF(OR($B28="",N(設定!$D18)=0),"",IF(N(設定!$D18)=MONTH(J$24),N(設定!$C18),0)) -> 0 | ... N28: =IF(OR($B28="",N(設定!$D18)=0),"",IF(N(設定!$D18)=MONTH(N$24),N(設定!$C18),0)) -> 40000 | O28: =IF($B28="","",SUM(C28:N28)) -> 40000
B29: =B10 -> お中元・お歳暮 | C29: =IF(OR($B29="",N(設定!$D19)=0),"",IF(N(設定!$D19)=MONTH(C$24),N(設定!$C19),0)) -> 0 | D29: =IF(OR($B29="",N(設定!$D19)=0),"",IF(N(設定!$D19)=MONTH(D$24),N(設定!$C19),0)) -> 0 | E29: =IF(OR($B29="",N(設定!$D19)=0),"",IF(N(設定!$D19)=MONTH(E$24),N(設定!$C19),0)) -> 0 | F29: =IF(OR($B29="",N(設定!$D19)=0),"",IF(N(設定!$D19)=MONTH(F$24),N(設定!$C19),0)) -> 0 | G29: =IF(OR($B29="",N(設定!$D19)=0),"",IF(N(設定!$D19)=MONTH(G$24),N(設定!$C19),0)) -> 0 | H29: =IF(OR($B29="",N(設定!$D19)=0),"",IF(N(設定!$D19)=MONTH(H$24),N(設定!$C19),0)) -> 0 | I29: =IF(OR($B29="",N(設定!$D19)=0),"",IF(N(設定!$D19)=MONTH(I$24),N(設定!$C19),0)) -> 20000 | J29: =IF(OR($B29="",N(設定!$D19)=0),"",IF(N(設定!$D19)=MONTH(J$24),N(設定!$C19),0)) -> 0 | ... N29: =IF(OR($B29="",N(設定!$D19)=0),"",IF(N(設定!$D19)=MONTH(N$24),N(設定!$C19),0)) -> 0 | O29: =IF($B29="","",SUM(C29:N29)) -> 20000
B30: =B11 -> 美容（ヘア・ネイル） | C30: =IF(OR($B30="",N(設定!$D20)=0),"",IF(N(設定!$D20)=MONTH(C$24),N(設定!$C20),0)) | D30: =IF(OR($B30="",N(設定!$D20)=0),"",IF(N(設定!$D20)=MONTH(D$24),N(設定!$C20),0)) | E30: =IF(OR($B30="",N(設定!$D20)=0),"",IF(N(設定!$D20)=MONTH(E$24),N(設定!$C20),0)) | F30: =IF(OR($B30="",N(設定!$D20)=0),"",IF(N(設定!$D20)=MONTH(F$24),N(設定!$C20),0)) | G30: =IF(OR($B30="",N(設定!$D20)=0),"",IF(N(設定!$D20)=MONTH(G$24),N(設定!$C20),0)) | H30: =IF(OR($B30="",N(設定!$D20)=0),"",IF(N(設定!$D20)=MONTH(H$24),N(設定!$C20),0)) | I30: =IF(OR($B30="",N(設定!$D20)=0),"",IF(N(設定!$D20)=MONTH(I$24),N(設定!$C20),0)) | J30: =IF(OR($B30="",N(設定!$D20)=0),"",IF(N(設定!$D20)=MONTH(J$24),N(設定!$C20),0)) | ... N30: =IF(OR($B30="",N(設定!$D20)=0),"",IF(N(設定!$D20)=MONTH(N$24),N(設定!$C20),0)) | O30: =IF($B30="","",SUM(C30:N30)) -> 0
B31: =B12 -> 推し活・イベント | C31: =IF(OR($B31="",N(設定!$D21)=0),"",IF(N(設定!$D21)=MONTH(C$24),N(設定!$C21),0)) -> 0 | D31: =IF(OR($B31="",N(設定!$D21)=0),"",IF(N(設定!$D21)=MONTH(D$24),N(設定!$C21),0)) -> 0 | E31: =IF(OR($B31="",N(設定!$D21)=0),"",IF(N(設定!$D21)=MONTH(E$24),N(設定!$C21),0)) -> 0 | F31: =IF(OR($B31="",N(設定!$D21)=0),"",IF(N(設定!$D21)=MONTH(F$24),N(設定!$C21),0)) -> 0 | G31: =IF(OR($B31="",N(設定!$D21)=0),"",IF(N(設定!$D21)=MONTH(G$24),N(設定!$C21),0)) -> 0 | H31: =IF(OR($B31="",N(設定!$D21)=0),"",IF(N(設定!$D21)=MONTH(H$24),N(設定!$C21),0)) -> 0 | I31: =IF(OR($B31="",N(設定!$D21)=0),"",IF(N(設定!$D21)=MONTH(I$24),N(設定!$C21),0)) -> 0 | J31: =IF(OR($B31="",N(設定!$D21)=0),"",IF(N(設定!$D21)=MONTH(J$24),N(設定!$C21),0)) -> 0 | ... N31: =IF(OR($B31="",N(設定!$D21)=0),"",IF(N(設定!$D21)=MONTH(N$24),N(設定!$C21),0)) -> 0 | O31: =IF($B31="","",SUM(C31:N31)) -> 50000
B32: =B13 -> 家電・家具の買い替え | C32: =IF(OR($B32="",N(設定!$D22)=0),"",IF(N(設定!$D22)=MONTH(C$24),N(設定!$C22),0)) -> 0 | D32: =IF(OR($B32="",N(設定!$D22)=0),"",IF(N(設定!$D22)=MONTH(D$24),N(設定!$C22),0)) -> 0 | E32: =IF(OR($B32="",N(設定!$D22)=0),"",IF(N(設定!$D22)=MONTH(E$24),N(設定!$C22),0)) -> 0 | F32: =IF(OR($B32="",N(設定!$D22)=0),"",IF(N(設定!$D22)=MONTH(F$24),N(設定!$C22),0)) -> 0 | G32: =IF(OR($B32="",N(設定!$D22)=0),"",IF(N(設定!$D22)=MONTH(G$24),N(設定!$C22),0)) -> 0 | H32: =IF(OR($B32="",N(設定!$D22)=0),"",IF(N(設定!$D22)=MONTH(H$24),N(設定!$C22),0)) -> 0 | I32: =IF(OR($B32="",N(設定!$D22)=0),"",IF(N(設定!$D22)=MONTH(I$24),N(設定!$C22),0)) -> 0 | J32: =IF(OR($B32="",N(設定!$D22)=0),"",IF(N(設定!$D22)=MONTH(J$24),N(設定!$C22),0)) -> 0 | ... N32: =IF(OR($B32="",N(設定!$D22)=0),"",IF(N(設定!$D22)=MONTH(N$24),N(設定!$C22),0)) -> 0 | O32: =IF($B32="","",SUM(C32:N32)) -> 40000
B33: =B14 -> 資格・習い事 | C33: =IF(OR($B33="",N(設定!$D23)=0),"",IF(N(設定!$D23)=MONTH(C$24),N(設定!$C23),0)) -> 0 | D33: =IF(OR($B33="",N(設定!$D23)=0),"",IF(N(設定!$D23)=MONTH(D$24),N(設定!$C23),0)) -> 0 | E33: =IF(OR($B33="",N(設定!$D23)=0),"",IF(N(設定!$D23)=MONTH(E$24),N(設定!$C23),0)) -> 0 | F33: =IF(OR($B33="",N(設定!$D23)=0),"",IF(N(設定!$D23)=MONTH(F$24),N(設定!$C23),0)) -> 30000 | G33: =IF(OR($B33="",N(設定!$D23)=0),"",IF(N(設定!$D23)=MONTH(G$24),N(設定!$C23),0)) -> 0 | H33: =IF(OR($B33="",N(設定!$D23)=0),"",IF(N(設定!$D23)=MONTH(H$24),N(設定!$C23),0)) -> 0 | I33: =IF(OR($B33="",N(設定!$D23)=0),"",IF(N(設定!$D23)=MONTH(I$24),N(設定!$C23),0)) -> 0 | J33: =IF(OR($B33="",N(設定!$D23)=0),"",IF(N(設定!$D23)=MONTH(J$24),N(設定!$C23),0)) -> 0 | ... N33: =IF(OR($B33="",N(設定!$D23)=0),"",IF(N(設定!$D23)=MONTH(N$24),N(設定!$C23),0)) -> 0 | O33: =IF($B33="","",SUM(C33:N33)) -> 30000
B34: =B15 -> 年払い（保険・サブスク） | C34: =IF(OR($B34="",N(設定!$D24)=0),"",IF(N(設定!$D24)=MONTH(C$24),N(設定!$C24),0)) -> 0 | D34: =IF(OR($B34="",N(設定!$D24)=0),"",IF(N(設定!$D24)=MONTH(D$24),N(設定!$C24),0)) -> 0 | E34: =IF(OR($B34="",N(設定!$D24)=0),"",IF(N(設定!$D24)=MONTH(E$24),N(設定!$C24),0)) -> 0 | F34: =IF(OR($B34="",N(設定!$D24)=0),"",IF(N(設定!$D24)=MONTH(F$24),N(設定!$C24),0)) -> 0 | G34: =IF(OR($B34="",N(設定!$D24)=0),"",IF(N(設定!$D24)=MONTH(G$24),N(設定!$C24),0)) -> 0 | H34: =IF(OR($B34="",N(設定!$D24)=0),"",IF(N(設定!$D24)=MONTH(H$24),N(設定!$C24),0)) -> 0 | I34: =IF(OR($B34="",N(設定!$D24)=0),"",IF(N(設定!$D24)=MONTH(I$24),N(設定!$C24),0)) -> 0 | J34: =IF(OR($B34="",N(設定!$D24)=0),"",IF(N(設定!$D24)=MONTH(J$24),N(設定!$C24),0)) -> 0 | ... N34: =IF(OR($B34="",N(設定!$D24)=0),"",IF(N(設定!$D24)=MONTH(N$24),N(設定!$C24),0)) -> 0 | O34: =IF($B34="","",SUM(C34:N34)) -> 30000
B35: =B16 -> その他（予備費） | C35: =IF(OR($B35="",N(設定!$D25)=0),"",IF(N(設定!$D25)=MONTH(C$24),N(設定!$C25),0)) | D35: =IF(OR($B35="",N(設定!$D25)=0),"",IF(N(設定!$D25)=MONTH(D$24),N(設定!$C25),0)) | E35: =IF(OR($B35="",N(設定!$D25)=0),"",IF(N(設定!$D25)=MONTH(E$24),N(設定!$C25),0)) | F35: =IF(OR($B35="",N(設定!$D25)=0),"",IF(N(設定!$D25)=MONTH(F$24),N(設定!$C25),0)) | G35: =IF(OR($B35="",N(設定!$D25)=0),"",IF(N(設定!$D25)=MONTH(G$24),N(設定!$C25),0)) | H35: =IF(OR($B35="",N(設定!$D25)=0),"",IF(N(設定!$D25)=MONTH(H$24),N(設定!$C25),0)) | I35: =IF(OR($B35="",N(設定!$D25)=0),"",IF(N(設定!$D25)=MONTH(I$24),N(設定!$C25),0)) | J35: =IF(OR($B35="",N(設定!$D25)=0),"",IF(N(設定!$D25)=MONTH(J$24),N(設定!$C25),0)) | ... N35: =IF(OR($B35="",N(設定!$D25)=0),"",IF(N(設定!$D25)=MONTH(N$24),N(設定!$C25),0)) | O35: =IF($B35="","",SUM(C35:N35)) -> 0
B36: =B17 | C36: =IF(OR($B36="",N(設定!$D26)=0),"",IF(N(設定!$D26)=MONTH(C$24),N(設定!$C26),0)) | D36: =IF(OR($B36="",N(設定!$D26)=0),"",IF(N(設定!$D26)=MONTH(D$24),N(設定!$C26),0)) | E36: =IF(OR($B36="",N(設定!$D26)=0),"",IF(N(設定!$D26)=MONTH(E$24),N(設定!$C26),0)) | F36: =IF(OR($B36="",N(設定!$D26)=0),"",IF(N(設定!$D26)=MONTH(F$24),N(設定!$C26),0)) | G36: =IF(OR($B36="",N(設定!$D26)=0),"",IF(N(設定!$D26)=MONTH(G$24),N(設定!$C26),0)) | H36: =IF(OR($B36="",N(設定!$D26)=0),"",IF(N(設定!$D26)=MONTH(H$24),N(設定!$C26),0)) | I36: =IF(OR($B36="",N(設定!$D26)=0),"",IF(N(設定!$D26)=MONTH(I$24),N(設定!$C26),0)) | J36: =IF(OR($B36="",N(設定!$D26)=0),"",IF(N(設定!$D26)=MONTH(J$24),N(設定!$C26),0)) | ... N36: =IF(OR($B36="",N(設定!$D26)=0),"",IF(N(設定!$D26)=MONTH(N$24),N(設定!$C26),0)) | O36: =IF($B36="","",SUM(C36:N36))
... B39: =B20 | C39: =IF(OR($B39="",N(設定!$D29)=0),"",IF(N(設定!$D29)=MONTH(C$24),N(設定!$C29),0)) | D39: =IF(OR($B39="",N(設定!$D29)=0),"",IF(N(設定!$D29)=MONTH(D$24),N(設定!$C29),0)) | E39: =IF(OR($B39="",N(設定!$D29)=0),"",IF(N(設定!$D29)=MONTH(E$24),N(設定!$C29),0)) | F39: =IF(OR($B39="",N(設定!$D29)=0),"",IF(N(設定!$D29)=MONTH(F$24),N(設定!$C29),0)) | G39: =IF(OR($B39="",N(設定!$D29)=0),"",IF(N(設定!$D29)=MONTH(G$24),N(設定!$C29),0)) | H39: =IF(OR($B39="",N(設定!$D29)=0),"",IF(N(設定!$D29)=MONTH(H$24),N(設定!$C29),0)) | I39: =IF(OR($B39="",N(設定!$D29)=0),"",IF(N(設定!$D29)=MONTH(I$24),N(設定!$C29),0)) | J39: =IF(OR($B39="",N(設定!$D29)=0),"",IF(N(設定!$D29)=MONTH(J$24),N(設定!$C29),0)) | ... N39: =IF(OR($B39="",N(設定!$D29)=0),"",IF(N(設定!$D29)=MONTH(N$24),N(設定!$C29),0)) | O39: =IF($B39="","",SUM(C39:N39))
B40: 合計 | C40: =SUM(C25:C39) -> 0 | D40: =SUM(D25:D39) -> 0 | E40: =SUM(E25:E39) -> 30000 | F40: =SUM(F25:F39) -> 30000 | G40: =SUM(G25:G39) -> 0 | H40: =SUM(H25:H39) -> 60000 | I40: =SUM(I25:I39) -> 20000 | J40: =SUM(J25:J39) -> 80000 | ... O40: =SUM(O25:O39) -> 380000
B42: ③ 積立残高の推移（月末時点の目安）
B43: 項目 | C43: =C$5 -> 46023 | D43: =D$5 -> 46054 | E43: =E$5 -> 46082 | F43: =F$5 -> 46113 | G43: =G$5 -> 46143 | H43: =H$5 -> 46174 | I43: =I$5 -> 46204 | J43: =J$5 -> 46235 | ... N43: =N$5 -> 46357
B44: =B6 -> 帰省・旅行 | C44: =IF($B44="","",N(設定!$E15)+ROUNDUP(N(設定!$C15)/12,0)*COLUMNS($C44:C44)-SUM($C6:C6)) -> 6667 | D44: =IF($B44="","",N(設定!$E15)+ROUNDUP(N(設定!$C15)/12,0)*COLUMNS($C44:D44)-SUM($C6:D6)) -> 13334 | E44: =IF($B44="","",N(設定!$E15)+ROUNDUP(N(設定!$C15)/12,0)*COLUMNS($C44:E44)-SUM($C6:E6)) -> 20001 | F44: =IF($B44="","",N(設定!$E15)+ROUNDUP(N(設定!$C15)/12,0)*COLUMNS($C44:F44)-SUM($C6:F6)) -> 26668 | G44: =IF($B44="","",N(設定!$E15)+ROUNDUP(N(設定!$C15)/12,0)*COLUMNS($C44:G44)-SUM($C6:G6)) -> 33335 | H44: =IF($B44="","",N(設定!$E15)+ROUNDUP(N(設定!$C15)/12,0)*COLUMNS($C44:H44)-SUM($C6:H6)) -> 40002 | I44: =IF($B44="","",N(設定!$E15)+ROUNDUP(N(設定!$C15)/12,0)*COLUMNS($C44:I44)-SUM($C6:I6)) -> 46669 | J44: =IF($B44="","",N(設定!$E15)+ROUNDUP(N(設定!$C15)/12,0)*COLUMNS($C44:J44)-SUM($C6:J6)) -> 53336 | ... N44: =IF($B44="","",N(設定!$E15)+ROUNDUP(N(設定!$C15)/12,0)*COLUMNS($C44:N44)-SUM($C6:N6)) -> 80004
B45: =B7 -> 冠婚葬祭（ご祝儀・香典） | C45: =IF($B45="","",N(設定!$E16)+ROUNDUP(N(設定!$C16)/12,0)*COLUMNS($C45:C45)-SUM($C7:C7)) -> 5000 | D45: =IF($B45="","",N(設定!$E16)+ROUNDUP(N(設定!$C16)/12,0)*COLUMNS($C45:D45)-SUM($C7:D7)) -> 10000 | E45: =IF($B45="","",N(設定!$E16)+ROUNDUP(N(設定!$C16)/12,0)*COLUMNS($C45:E45)-SUM($C7:E7)) -> 15000 | F45: =IF($B45="","",N(設定!$E16)+ROUNDUP(N(設定!$C16)/12,0)*COLUMNS($C45:F45)-SUM($C7:F7)) -> 20000 | G45: =IF($B45="","",N(設定!$E16)+ROUNDUP(N(設定!$C16)/12,0)*COLUMNS($C45:G45)-SUM($C7:G7)) -> 25000 | H45: =IF($B45="","",N(設定!$E16)+ROUNDUP(N(設定!$C16)/12,0)*COLUMNS($C45:H45)-SUM($C7:H7)) -> 30000 | I45: =IF($B45="","",N(設定!$E16)+ROUNDUP(N(設定!$C16)/12,0)*COLUMNS($C45:I45)-SUM($C7:I7)) -> 35000 | J45: =IF($B45="","",N(設定!$E16)+ROUNDUP(N(設定!$C16)/12,0)*COLUMNS($C45:J45)-SUM($C7:J7)) -> 40000 | ... N45: =IF($B45="","",N(設定!$E16)+ROUNDUP(N(設定!$C16)/12,0)*COLUMNS($C45:N45)-SUM($C7:N7)) -> 60000
B46: =B8 -> 誕生日・記念日 | C46: =IF($B46="","",N(設定!$E17)+ROUNDUP(N(設定!$C17)/12,0)*COLUMNS($C46:C46)-SUM($C8:C8)) -> 2500 | D46: =IF($B46="","",N(設定!$E17)+ROUNDUP(N(設定!$C17)/12,0)*COLUMNS($C46:D46)-SUM($C8:D8)) -> 5000 | E46: =IF($B46="","",N(設定!$E17)+ROUNDUP(N(設定!$C17)/12,0)*COLUMNS($C46:E46)-SUM($C8:E8)) -> 7500 | F46: =IF($B46="","",N(設定!$E17)+ROUNDUP(N(設定!$C17)/12,0)*COLUMNS($C46:F46)-SUM($C8:F8)) -> 10000 | G46: =IF($B46="","",N(設定!$E17)+ROUNDUP(N(設定!$C17)/12,0)*COLUMNS($C46:G46)-SUM($C8:G8)) -> 12500 | H46: =IF($B46="","",N(設定!$E17)+ROUNDUP(N(設定!$C17)/12,0)*COLUMNS($C46:H46)-SUM($C8:H8)) -> 15000 | I46: =IF($B46="","",N(設定!$E17)+ROUNDUP(N(設定!$C17)/12,0)*COLUMNS($C46:I46)-SUM($C8:I8)) -> 17500 | J46: =IF($B46="","",N(設定!$E17)+ROUNDUP(N(設定!$C17)/12,0)*COLUMNS($C46:J46)-SUM($C8:J8)) -> 20000 | ... N46: =IF($B46="","",N(設定!$E17)+ROUNDUP(N(設定!$C17)/12,0)*COLUMNS($C46:N46)-SUM($C8:N8)) -> 30000
B47: =B9 -> クリスマス・年末年始 | C47: =IF($B47="","",N(設定!$E18)+ROUNDUP(N(設定!$C18)/12,0)*COLUMNS($C47:C47)-SUM($C9:C9)) -> 3334 | D47: =IF($B47="","",N(設定!$E18)+ROUNDUP(N(設定!$C18)/12,0)*COLUMNS($C47:D47)-SUM($C9:D9)) -> 6668 | E47: =IF($B47="","",N(設定!$E18)+ROUNDUP(N(設定!$C18)/12,0)*COLUMNS($C47:E47)-SUM($C9:E9)) -> 10002 | F47: =IF($B47="","",N(設定!$E18)+ROUNDUP(N(設定!$C18)/12,0)*COLUMNS($C47:F47)-SUM($C9:F9)) -> 13336 | G47: =IF($B47="","",N(設定!$E18)+ROUNDUP(N(設定!$C18)/12,0)*COLUMNS($C47:G47)-SUM($C9:G9)) -> 16670 | H47: =IF($B47="","",N(設定!$E18)+ROUNDUP(N(設定!$C18)/12,0)*COLUMNS($C47:H47)-SUM($C9:H9)) -> 20004 | I47: =IF($B47="","",N(設定!$E18)+ROUNDUP(N(設定!$C18)/12,0)*COLUMNS($C47:I47)-SUM($C9:I9)) -> 23338 | J47: =IF($B47="","",N(設定!$E18)+ROUNDUP(N(設定!$C18)/12,0)*COLUMNS($C47:J47)-SUM($C9:J9)) -> 26672 | ... N47: =IF($B47="","",N(設定!$E18)+ROUNDUP(N(設定!$C18)/12,0)*COLUMNS($C47:N47)-SUM($C9:N9)) -> 40008
...
